2024-08-13 15:36:00,473 INFO    StreamThr :35628 [internal.py:wandb_internal():85] W&B internal server running at pid: 35628, started at: 2024-08-13 15:36:00.473131
2024-08-13 15:36:00,474 DEBUG   HandlerThread:35628 [handler.py:handle_request():158] handle_request: status
2024-08-13 15:36:00,477 INFO    WriterThread:35628 [datastore.py:open_for_write():87] open: /Users/alexracape/Programming/blokus_backend/wandb/run-20240813_153600-mevdf0js/run-mevdf0js.wandb
2024-08-13 15:36:00,477 DEBUG   SenderThread:35628 [sender.py:send():391] send: header
2024-08-13 15:36:00,498 DEBUG   SenderThread:35628 [sender.py:send():391] send: run
2024-08-13 15:36:00,680 ERROR   SenderThread:35628 [internal_api.py:execute():349] 403 response executing GraphQL.
2024-08-13 15:36:00,680 ERROR   SenderThread:35628 [internal_api.py:execute():350] {"errors":[{"message":"permission denied","path":["upsertBucket"],"extensions":{"code":"PERMISSION_ERROR"}}],"data":{"upsertBucket":null}}
2024-08-13 15:36:00,680 ERROR   SenderThread:35628 [sender.py:send_run():1021] It appears that you do not have permission to access the requested resource. Please reach out to the project owner to grant you access. If you have the correct permissions, verify that there are no issues with your networking setup.(Error 403: Forbidden)
Traceback (most recent call last):
  File "/Users/alexracape/Programming/blokus_backend/venv/lib/python3.10/site-packages/wandb/sdk/lib/retry.py", line 131, in __call__
    result = self._call_fn(*args, **kwargs)
  File "/Users/alexracape/Programming/blokus_backend/venv/lib/python3.10/site-packages/wandb/sdk/internal/internal_api.py", line 345, in execute
    return self.client.execute(*args, **kwargs)  # type: ignore
  File "/Users/alexracape/Programming/blokus_backend/venv/lib/python3.10/site-packages/wandb/vendor/gql-0.2.0/wandb_gql/client.py", line 52, in execute
    result = self._get_result(document, *args, **kwargs)
  File "/Users/alexracape/Programming/blokus_backend/venv/lib/python3.10/site-packages/wandb/vendor/gql-0.2.0/wandb_gql/client.py", line 60, in _get_result
    return self.transport.execute(document, *args, **kwargs)
  File "/Users/alexracape/Programming/blokus_backend/venv/lib/python3.10/site-packages/wandb/sdk/lib/gql_request.py", line 59, in execute
    request.raise_for_status()
  File "/Users/alexracape/Programming/blokus_backend/venv/lib/python3.10/site-packages/requests/models.py", line 1024, in raise_for_status
    raise HTTPError(http_error_msg, response=self)
requests.exceptions.HTTPError: 403 Client Error: Forbidden for url: https://api.wandb.ai/graphql

During handling of the above exception, another exception occurred:

Traceback (most recent call last):
  File "/Users/alexracape/Programming/blokus_backend/venv/lib/python3.10/site-packages/wandb/sdk/internal/sender.py", line 1019, in send_run
    server_run = self._init_run(run, config_value_dict)
  File "/Users/alexracape/Programming/blokus_backend/venv/lib/python3.10/site-packages/wandb/sdk/internal/sender.py", line 1091, in _init_run
    server_run, inserted, server_messages = self._api.upsert_run(
  File "/Users/alexracape/Programming/blokus_backend/venv/lib/python3.10/site-packages/wandb/apis/normalize.py", line 73, in wrapper
    raise err
  File "/Users/alexracape/Programming/blokus_backend/venv/lib/python3.10/site-packages/wandb/apis/normalize.py", line 41, in wrapper
    return func(*args, **kwargs)
  File "/Users/alexracape/Programming/blokus_backend/venv/lib/python3.10/site-packages/wandb/sdk/internal/internal_api.py", line 2224, in upsert_run
    response = self.gql(
  File "/Users/alexracape/Programming/blokus_backend/venv/lib/python3.10/site-packages/wandb/sdk/internal/internal_api.py", line 317, in gql
    ret = self._retry_gql(
  File "/Users/alexracape/Programming/blokus_backend/venv/lib/python3.10/site-packages/wandb/sdk/lib/retry.py", line 147, in __call__
    retry_timedelta_triggered = check_retry_fn(e)
  File "/Users/alexracape/Programming/blokus_backend/venv/lib/python3.10/site-packages/wandb/util.py", line 968, in check_retry_fn
    return fallback_retry_fn(e)
  File "/Users/alexracape/Programming/blokus_backend/venv/lib/python3.10/site-packages/wandb/util.py", line 910, in no_retry_auth
    raise CommError(
wandb.errors.CommError: It appears that you do not have permission to access the requested resource. Please reach out to the project owner to grant you access. If you have the correct permissions, verify that there are no issues with your networking setup.(Error 403: Forbidden)
2024-08-13 15:36:00,811 DEBUG   HandlerThread:35628 [handler.py:handle_request():158] handle_request: shutdown
2024-08-13 15:36:00,811 INFO    HandlerThread:35628 [handler.py:finish():882] shutting down handler
2024-08-13 15:36:01,510 INFO    WriterThread:35628 [datastore.py:close():296] close: /Users/alexracape/Programming/blokus_backend/wandb/run-20240813_153600-mevdf0js/run-mevdf0js.wandb
2024-08-13 15:36:01,687 INFO    SenderThread:35628 [sender.py:finish():1631] shutting down sender
